2017-11-08 10:06:58.537540~ Traceback (most recent call last):
  File "D:\Phyton\bot\decorators.py", line 10, in wrap
    func(*args,**kargs)
  File "D:\Phyton\bot\bot.py", line 291, in balance
    print(list(keyboard))
TypeError: 'ReplyKeyboardMarkup' object is not iterable
 

2017-11-08 10:07:15.243210~ Traceback (most recent call last):
  File "D:\Phyton\bot\decorators.py", line 10, in wrap
    func(*args,**kargs)
  File "D:\Phyton\bot\bot.py", line 292, in balance
    print(list(keyboard))
TypeError: 'ReplyKeyboardMarkup' object is not iterable
 

2017-11-08 10:11:30.293717~ Traceback (most recent call last):
  File "D:\Phyton\bot\decorators.py", line 10, in wrap
    func(*args,**kargs)
  File "D:\Phyton\bot\decorators.py", line 33, in wrap
    func(message)
  File "D:\Phyton\bot\bot.py", line 311, in nomCard
    if message.text not in nomCard.comands:
AttributeError: 'function' object has no attribute 'comands'
 

2017-11-08 14:21:18.032050~ Traceback (most recent call last):
  File "D:\Phyton\bot\bot.py", line 818, in gogo
    bot.polling(none_stop=True)
  File "D:\Phyton\lib\site-packages\telebot\__init__.py", line 264, in polling
    self.__threaded_polling(none_stop, interval, timeout)
  File "D:\Phyton\lib\site-packages\telebot\__init__.py", line 288, in __threaded_polling
    self.worker_pool.raise_exceptions()
  File "D:\Phyton\lib\site-packages\telebot\util.py", line 107, in raise_exceptions
    six.reraise(self.exc_info[0], self.exc_info[1], self.exc_info[2])
  File "D:\Phyton\lib\site-packages\six.py", line 693, in reraise
    raise value
  File "D:\Phyton\lib\site-packages\telebot\util.py", line 58, in run
    task(*args, **kwargs)
  File "D:\Phyton\bot\bot.py", line 811, in db
    for i in row:
NameError: name 'row' is not defined
 

2017-11-08 14:21:23.087050~ Traceback (most recent call last):
  File "D:\Phyton\bot\bot.py", line 818, in gogo
    bot.polling(none_stop=True)
  File "D:\Phyton\lib\site-packages\telebot\__init__.py", line 264, in polling
    self.__threaded_polling(none_stop, interval, timeout)
  File "D:\Phyton\lib\site-packages\telebot\__init__.py", line 288, in __threaded_polling
    self.worker_pool.raise_exceptions()
  File "D:\Phyton\lib\site-packages\telebot\util.py", line 107, in raise_exceptions
    six.reraise(self.exc_info[0], self.exc_info[1], self.exc_info[2])
  File "D:\Phyton\lib\site-packages\six.py", line 692, in reraise
    raise value.with_traceback(tb)
  File "D:\Phyton\lib\site-packages\telebot\util.py", line 58, in run
    task(*args, **kwargs)
  File "D:\Phyton\bot\bot.py", line 811, in db
    for i in row:
NameError: name 'row' is not defined
 

2017-11-08 14:21:28.092050~ Traceback (most recent call last):
  File "D:\Phyton\bot\bot.py", line 818, in gogo
    bot.polling(none_stop=True)
  File "D:\Phyton\lib\site-packages\telebot\__init__.py", line 264, in polling
    self.__threaded_polling(none_stop, interval, timeout)
  File "D:\Phyton\lib\site-packages\telebot\__init__.py", line 288, in __threaded_polling
    self.worker_pool.raise_exceptions()
  File "D:\Phyton\lib\site-packages\telebot\util.py", line 107, in raise_exceptions
    six.reraise(self.exc_info[0], self.exc_info[1], self.exc_info[2])
  File "D:\Phyton\lib\site-packages\six.py", line 692, in reraise
    raise value.with_traceback(tb)
  File "D:\Phyton\lib\site-packages\telebot\util.py", line 58, in run
    task(*args, **kwargs)
  File "D:\Phyton\bot\bot.py", line 811, in db
    for i in row:
NameError: name 'row' is not defined
 

2017-11-08 14:28:49.069528~ Traceback (most recent call last):
  File "D:\Phyton\bot\bot.py", line 786, in gogo
    bot.polling(none_stop=True)
  File "D:\Phyton\lib\site-packages\telebot\__init__.py", line 264, in polling
    self.__threaded_polling(none_stop, interval, timeout)
  File "D:\Phyton\lib\site-packages\telebot\__init__.py", line 288, in __threaded_polling
    self.worker_pool.raise_exceptions()
  File "D:\Phyton\lib\site-packages\telebot\util.py", line 107, in raise_exceptions
    six.reraise(self.exc_info[0], self.exc_info[1], self.exc_info[2])
  File "D:\Phyton\lib\site-packages\six.py", line 693, in reraise
    raise value
  File "D:\Phyton\lib\site-packages\telebot\util.py", line 58, in run
    task(*args, **kwargs)
  File "D:\Phyton\bot\bot.py", line 780, in db
    request('2330004052223','01.10.2017','20.10.2017')
NameError: name 'request' is not defined
 

2017-11-08 14:28:54.077028~ Traceback (most recent call last):
  File "D:\Phyton\bot\bot.py", line 786, in gogo
    bot.polling(none_stop=True)
  File "D:\Phyton\lib\site-packages\telebot\__init__.py", line 264, in polling
    self.__threaded_polling(none_stop, interval, timeout)
  File "D:\Phyton\lib\site-packages\telebot\__init__.py", line 288, in __threaded_polling
    self.worker_pool.raise_exceptions()
  File "D:\Phyton\lib\site-packages\telebot\util.py", line 107, in raise_exceptions
    six.reraise(self.exc_info[0], self.exc_info[1], self.exc_info[2])
  File "D:\Phyton\lib\site-packages\six.py", line 692, in reraise
    raise value.with_traceback(tb)
  File "D:\Phyton\lib\site-packages\telebot\util.py", line 58, in run
    task(*args, **kwargs)
  File "D:\Phyton\bot\bot.py", line 780, in db
    request('2330004052223','01.10.2017','20.10.2017')
NameError: name 'request' is not defined
 

2017-11-08 14:28:59.082529~ Traceback (most recent call last):
  File "D:\Phyton\bot\bot.py", line 786, in gogo
    bot.polling(none_stop=True)
  File "D:\Phyton\lib\site-packages\telebot\__init__.py", line 264, in polling
    self.__threaded_polling(none_stop, interval, timeout)
  File "D:\Phyton\lib\site-packages\telebot\__init__.py", line 288, in __threaded_polling
    self.worker_pool.raise_exceptions()
  File "D:\Phyton\lib\site-packages\telebot\util.py", line 107, in raise_exceptions
    six.reraise(self.exc_info[0], self.exc_info[1], self.exc_info[2])
  File "D:\Phyton\lib\site-packages\six.py", line 692, in reraise
    raise value.with_traceback(tb)
  File "D:\Phyton\lib\site-packages\telebot\util.py", line 58, in run
    task(*args, **kwargs)
  File "D:\Phyton\bot\bot.py", line 780, in db
    request('2330004052223','01.10.2017','20.10.2017')
NameError: name 'request' is not defined
 

2017-11-08 14:29:04.792100~ Traceback (most recent call last):
  File "D:\Phyton\bot\bot.py", line 786, in gogo
    bot.polling(none_stop=True)
  File "D:\Phyton\lib\site-packages\telebot\__init__.py", line 264, in polling
    self.__threaded_polling(none_stop, interval, timeout)
  File "D:\Phyton\lib\site-packages\telebot\__init__.py", line 288, in __threaded_polling
    self.worker_pool.raise_exceptions()
  File "D:\Phyton\lib\site-packages\telebot\util.py", line 107, in raise_exceptions
    six.reraise(self.exc_info[0], self.exc_info[1], self.exc_info[2])
  File "D:\Phyton\lib\site-packages\six.py", line 693, in reraise
    raise value
  File "D:\Phyton\lib\site-packages\telebot\util.py", line 58, in run
    task(*args, **kwargs)
  File "D:\Phyton\bot\bot.py", line 780, in db
    login.request('2330004052223','01.10.2017','20.10.2017')
  File "D:\Phyton\bot\login.py", line 116, in request
    for row in rows:
NameError: name 'rows' is not defined
 

2017-11-08 14:29:09.798600~ Traceback (most recent call last):
  File "D:\Phyton\bot\bot.py", line 786, in gogo
    bot.polling(none_stop=True)
  File "D:\Phyton\lib\site-packages\telebot\__init__.py", line 264, in polling
    self.__threaded_polling(none_stop, interval, timeout)
  File "D:\Phyton\lib\site-packages\telebot\__init__.py", line 288, in __threaded_polling
    self.worker_pool.raise_exceptions()
  File "D:\Phyton\lib\site-packages\telebot\util.py", line 107, in raise_exceptions
    six.reraise(self.exc_info[0], self.exc_info[1], self.exc_info[2])
  File "D:\Phyton\lib\site-packages\six.py", line 692, in reraise
    raise value.with_traceback(tb)
  File "D:\Phyton\lib\site-packages\telebot\util.py", line 58, in run
    task(*args, **kwargs)
  File "D:\Phyton\bot\bot.py", line 780, in db
    login.request('2330004052223','01.10.2017','20.10.2017')
  File "D:\Phyton\bot\login.py", line 116, in request
    for row in rows:
NameError: name 'rows' is not defined
 

2017-11-08 14:29:14.804101~ Traceback (most recent call last):
  File "D:\Phyton\bot\bot.py", line 786, in gogo
    bot.polling(none_stop=True)
  File "D:\Phyton\lib\site-packages\telebot\__init__.py", line 264, in polling
    self.__threaded_polling(none_stop, interval, timeout)
  File "D:\Phyton\lib\site-packages\telebot\__init__.py", line 288, in __threaded_polling
    self.worker_pool.raise_exceptions()
  File "D:\Phyton\lib\site-packages\telebot\util.py", line 107, in raise_exceptions
    six.reraise(self.exc_info[0], self.exc_info[1], self.exc_info[2])
  File "D:\Phyton\lib\site-packages\six.py", line 692, in reraise
    raise value.with_traceback(tb)
  File "D:\Phyton\lib\site-packages\telebot\util.py", line 58, in run
    task(*args, **kwargs)
  File "D:\Phyton\bot\bot.py", line 780, in db
    login.request('2330004052223','01.10.2017','20.10.2017')
  File "D:\Phyton\bot\login.py", line 116, in request
    for row in rows:
NameError: name 'rows' is not defined
 

2017-11-08 14:29:19.809601~ Traceback (most recent call last):
  File "D:\Phyton\bot\bot.py", line 786, in gogo
    bot.polling(none_stop=True)
  File "D:\Phyton\lib\site-packages\telebot\__init__.py", line 264, in polling
    self.__threaded_polling(none_stop, interval, timeout)
  File "D:\Phyton\lib\site-packages\telebot\__init__.py", line 288, in __threaded_polling
    self.worker_pool.raise_exceptions()
  File "D:\Phyton\lib\site-packages\telebot\util.py", line 107, in raise_exceptions
    six.reraise(self.exc_info[0], self.exc_info[1], self.exc_info[2])
  File "D:\Phyton\lib\site-packages\six.py", line 692, in reraise
    raise value.with_traceback(tb)
  File "D:\Phyton\lib\site-packages\telebot\util.py", line 58, in run
    task(*args, **kwargs)
  File "D:\Phyton\bot\bot.py", line 780, in db
    login.request('2330004052223','01.10.2017','20.10.2017')
  File "D:\Phyton\bot\login.py", line 116, in request
    for row in rows:
NameError: name 'rows' is not defined
 

2017-11-08 14:51:37.114925~ Traceback (most recent call last):
  File "D:\Phyton\bot\decorators.py", line 10, in wrap
    func(*args,**kargs)
  File "D:\Phyton\bot\bot.py", line 296, in balance
    mess=balance1(card[0][1],card[0][2],keyboard)
  File "D:\Phyton\bot\bot.py", line 273, in balance1
    a=login.req(card1,card2,language[str(message.from_user.id)])
NameError: name 'message' is not defined
 

2017-11-08 15:06:35.919043~ Traceback (most recent call last):
  File "D:\Phyton\bot\bot.py", line 797, in gogo
    bot.polling(none_stop=True)
  File "D:\Phyton\lib\site-packages\telebot\__init__.py", line 264, in polling
    self.__threaded_polling(none_stop, interval, timeout)
  File "D:\Phyton\lib\site-packages\telebot\__init__.py", line 288, in __threaded_polling
    self.worker_pool.raise_exceptions()
  File "D:\Phyton\lib\site-packages\telebot\util.py", line 107, in raise_exceptions
    six.reraise(self.exc_info[0], self.exc_info[1], self.exc_info[2])
  File "D:\Phyton\lib\site-packages\six.py", line 693, in reraise
    raise value
  File "D:\Phyton\lib\site-packages\telebot\util.py", line 58, in run
    task(*args, **kwargs)
  File "D:\Phyton\bot\decorators.py", line 33, in wrap
    func(message)
  File "D:\Phyton\bot\bot.py", line 369, in pas
    bot.register_next_step_handler(mess,logC)
  File "D:\Phyton\lib\site-packages\telebot\__init__.py", line 996, in register_next_step_handler
    chat_id = message.chat.id
AttributeError: 'NoneType' object has no attribute 'chat'
 

2017-11-08 15:06:40.926043~ Traceback (most recent call last):
  File "D:\Phyton\bot\bot.py", line 797, in gogo
    bot.polling(none_stop=True)
  File "D:\Phyton\lib\site-packages\telebot\__init__.py", line 264, in polling
    self.__threaded_polling(none_stop, interval, timeout)
  File "D:\Phyton\lib\site-packages\telebot\__init__.py", line 288, in __threaded_polling
    self.worker_pool.raise_exceptions()
  File "D:\Phyton\lib\site-packages\telebot\util.py", line 107, in raise_exceptions
    six.reraise(self.exc_info[0], self.exc_info[1], self.exc_info[2])
  File "D:\Phyton\lib\site-packages\six.py", line 692, in reraise
    raise value.with_traceback(tb)
  File "D:\Phyton\lib\site-packages\telebot\util.py", line 58, in run
    task(*args, **kwargs)
  File "D:\Phyton\bot\decorators.py", line 33, in wrap
    func(message)
  File "D:\Phyton\bot\bot.py", line 369, in pas
    bot.register_next_step_handler(mess,logC)
  File "D:\Phyton\lib\site-packages\telebot\__init__.py", line 996, in register_next_step_handler
    chat_id = message.chat.id
AttributeError: 'NoneType' object has no attribute 'chat'
 

2017-11-08 15:06:45.931043~ Traceback (most recent call last):
  File "D:\Phyton\bot\bot.py", line 797, in gogo
    bot.polling(none_stop=True)
  File "D:\Phyton\lib\site-packages\telebot\__init__.py", line 264, in polling
    self.__threaded_polling(none_stop, interval, timeout)
  File "D:\Phyton\lib\site-packages\telebot\__init__.py", line 288, in __threaded_polling
    self.worker_pool.raise_exceptions()
  File "D:\Phyton\lib\site-packages\telebot\util.py", line 107, in raise_exceptions
    six.reraise(self.exc_info[0], self.exc_info[1], self.exc_info[2])
  File "D:\Phyton\lib\site-packages\six.py", line 692, in reraise
    raise value.with_traceback(tb)
  File "D:\Phyton\lib\site-packages\telebot\util.py", line 58, in run
    task(*args, **kwargs)
  File "D:\Phyton\bot\decorators.py", line 33, in wrap
    func(message)
  File "D:\Phyton\bot\bot.py", line 369, in pas
    bot.register_next_step_handler(mess,logC)
  File "D:\Phyton\lib\site-packages\telebot\__init__.py", line 996, in register_next_step_handler
    chat_id = message.chat.id
AttributeError: 'NoneType' object has no attribute 'chat'
 

2017-11-08 15:06:46.293043~ Traceback (most recent call last):
  File "D:\Phyton\bot\decorators.py", line 10, in wrap
    func(*args,**kargs)
  File "D:\Phyton\bot\decorators.py", line 33, in wrap
    func(message)
  File "D:\Phyton\bot\bot.py", line 401, in choiceCard
    mess=balance3(card[0][1],card[0][1])
TypeError: balance3() missing 2 required positional arguments: 'keyboard' and 'message'
 

2017-11-08 15:06:50.936043~ Traceback (most recent call last):
  File "D:\Phyton\bot\bot.py", line 797, in gogo
    bot.polling(none_stop=True)
  File "D:\Phyton\lib\site-packages\telebot\__init__.py", line 264, in polling
    self.__threaded_polling(none_stop, interval, timeout)
  File "D:\Phyton\lib\site-packages\telebot\__init__.py", line 288, in __threaded_polling
    self.worker_pool.raise_exceptions()
  File "D:\Phyton\lib\site-packages\telebot\util.py", line 107, in raise_exceptions
    six.reraise(self.exc_info[0], self.exc_info[1], self.exc_info[2])
  File "D:\Phyton\lib\site-packages\six.py", line 692, in reraise
    raise value.with_traceback(tb)
  File "D:\Phyton\lib\site-packages\telebot\util.py", line 58, in run
    task(*args, **kwargs)
  File "D:\Phyton\bot\decorators.py", line 33, in wrap
    func(message)
  File "D:\Phyton\bot\bot.py", line 369, in pas
    bot.register_next_step_handler(mess,logC)
  File "D:\Phyton\lib\site-packages\telebot\__init__.py", line 996, in register_next_step_handler
    chat_id = message.chat.id
AttributeError: 'NoneType' object has no attribute 'chat'
 

2017-11-08 15:06:55.941043~ Traceback (most recent call last):
  File "D:\Phyton\bot\bot.py", line 797, in gogo
    bot.polling(none_stop=True)
  File "D:\Phyton\lib\site-packages\telebot\__init__.py", line 264, in polling
    self.__threaded_polling(none_stop, interval, timeout)
  File "D:\Phyton\lib\site-packages\telebot\__init__.py", line 288, in __threaded_polling
    self.worker_pool.raise_exceptions()
  File "D:\Phyton\lib\site-packages\telebot\util.py", line 107, in raise_exceptions
    six.reraise(self.exc_info[0], self.exc_info[1], self.exc_info[2])
  File "D:\Phyton\lib\site-packages\six.py", line 692, in reraise
    raise value.with_traceback(tb)
  File "D:\Phyton\lib\site-packages\telebot\util.py", line 58, in run
    task(*args, **kwargs)
  File "D:\Phyton\bot\decorators.py", line 33, in wrap
    func(message)
  File "D:\Phyton\bot\bot.py", line 369, in pas
    bot.register_next_step_handler(mess,logC)
  File "D:\Phyton\lib\site-packages\telebot\__init__.py", line 996, in register_next_step_handler
    chat_id = message.chat.id
AttributeError: 'NoneType' object has no attribute 'chat'
 

2017-11-08 15:07:00.943043~ Traceback (most recent call last):
  File "D:\Phyton\bot\bot.py", line 797, in gogo
    bot.polling(none_stop=True)
  File "D:\Phyton\lib\site-packages\telebot\__init__.py", line 264, in polling
    self.__threaded_polling(none_stop, interval, timeout)
  File "D:\Phyton\lib\site-packages\telebot\__init__.py", line 288, in __threaded_polling
    self.worker_pool.raise_exceptions()
  File "D:\Phyton\lib\site-packages\telebot\util.py", line 107, in raise_exceptions
    six.reraise(self.exc_info[0], self.exc_info[1], self.exc_info[2])
  File "D:\Phyton\lib\site-packages\six.py", line 692, in reraise
    raise value.with_traceback(tb)
  File "D:\Phyton\lib\site-packages\telebot\util.py", line 58, in run
    task(*args, **kwargs)
  File "D:\Phyton\bot\decorators.py", line 33, in wrap
    func(message)
  File "D:\Phyton\bot\bot.py", line 369, in pas
    bot.register_next_step_handler(mess,logC)
  File "D:\Phyton\lib\site-packages\telebot\__init__.py", line 996, in register_next_step_handler
    chat_id = message.chat.id
AttributeError: 'NoneType' object has no attribute 'chat'
 

2017-11-08 15:07:05.950043~ Traceback (most recent call last):
  File "D:\Phyton\bot\bot.py", line 797, in gogo
    bot.polling(none_stop=True)
  File "D:\Phyton\lib\site-packages\telebot\__init__.py", line 264, in polling
    self.__threaded_polling(none_stop, interval, timeout)
  File "D:\Phyton\lib\site-packages\telebot\__init__.py", line 288, in __threaded_polling
    self.worker_pool.raise_exceptions()
  File "D:\Phyton\lib\site-packages\telebot\util.py", line 107, in raise_exceptions
    six.reraise(self.exc_info[0], self.exc_info[1], self.exc_info[2])
  File "D:\Phyton\lib\site-packages\six.py", line 692, in reraise
    raise value.with_traceback(tb)
  File "D:\Phyton\lib\site-packages\telebot\util.py", line 58, in run
    task(*args, **kwargs)
  File "D:\Phyton\bot\decorators.py", line 33, in wrap
    func(message)
  File "D:\Phyton\bot\bot.py", line 369, in pas
    bot.register_next_step_handler(mess,logC)
  File "D:\Phyton\lib\site-packages\telebot\__init__.py", line 996, in register_next_step_handler
    chat_id = message.chat.id
AttributeError: 'NoneType' object has no attribute 'chat'
 

2017-11-08 15:07:10.954043~ Traceback (most recent call last):
  File "D:\Phyton\bot\bot.py", line 797, in gogo
    bot.polling(none_stop=True)
  File "D:\Phyton\lib\site-packages\telebot\__init__.py", line 264, in polling
    self.__threaded_polling(none_stop, interval, timeout)
  File "D:\Phyton\lib\site-packages\telebot\__init__.py", line 288, in __threaded_polling
    self.worker_pool.raise_exceptions()
  File "D:\Phyton\lib\site-packages\telebot\util.py", line 107, in raise_exceptions
    six.reraise(self.exc_info[0], self.exc_info[1], self.exc_info[2])
  File "D:\Phyton\lib\site-packages\six.py", line 692, in reraise
    raise value.with_traceback(tb)
  File "D:\Phyton\lib\site-packages\telebot\util.py", line 58, in run
    task(*args, **kwargs)
  File "D:\Phyton\bot\decorators.py", line 33, in wrap
    func(message)
  File "D:\Phyton\bot\bot.py", line 369, in pas
    bot.register_next_step_handler(mess,logC)
  File "D:\Phyton\lib\site-packages\telebot\__init__.py", line 996, in register_next_step_handler
    chat_id = message.chat.id
AttributeError: 'NoneType' object has no attribute 'chat'
 

2017-11-08 15:07:15.960043~ Traceback (most recent call last):
  File "D:\Phyton\bot\bot.py", line 797, in gogo
    bot.polling(none_stop=True)
  File "D:\Phyton\lib\site-packages\telebot\__init__.py", line 264, in polling
    self.__threaded_polling(none_stop, interval, timeout)
  File "D:\Phyton\lib\site-packages\telebot\__init__.py", line 288, in __threaded_polling
    self.worker_pool.raise_exceptions()
  File "D:\Phyton\lib\site-packages\telebot\util.py", line 107, in raise_exceptions
    six.reraise(self.exc_info[0], self.exc_info[1], self.exc_info[2])
  File "D:\Phyton\lib\site-packages\six.py", line 692, in reraise
    raise value.with_traceback(tb)
  File "D:\Phyton\lib\site-packages\telebot\util.py", line 58, in run
    task(*args, **kwargs)
  File "D:\Phyton\bot\decorators.py", line 33, in wrap
    func(message)
  File "D:\Phyton\bot\bot.py", line 369, in pas
    bot.register_next_step_handler(mess,logC)
  File "D:\Phyton\lib\site-packages\telebot\__init__.py", line 996, in register_next_step_handler
    chat_id = message.chat.id
AttributeError: 'NoneType' object has no attribute 'chat'
 

2017-11-08 15:07:20.965043~ Traceback (most recent call last):
  File "D:\Phyton\bot\bot.py", line 797, in gogo
    bot.polling(none_stop=True)
  File "D:\Phyton\lib\site-packages\telebot\__init__.py", line 264, in polling
    self.__threaded_polling(none_stop, interval, timeout)
  File "D:\Phyton\lib\site-packages\telebot\__init__.py", line 288, in __threaded_polling
    self.worker_pool.raise_exceptions()
  File "D:\Phyton\lib\site-packages\telebot\util.py", line 107, in raise_exceptions
    six.reraise(self.exc_info[0], self.exc_info[1], self.exc_info[2])
  File "D:\Phyton\lib\site-packages\six.py", line 692, in reraise
    raise value.with_traceback(tb)
  File "D:\Phyton\lib\site-packages\telebot\util.py", line 58, in run
    task(*args, **kwargs)
  File "D:\Phyton\bot\decorators.py", line 33, in wrap
    func(message)
  File "D:\Phyton\bot\bot.py", line 369, in pas
    bot.register_next_step_handler(mess,logC)
  File "D:\Phyton\lib\site-packages\telebot\__init__.py", line 996, in register_next_step_handler
    chat_id = message.chat.id
AttributeError: 'NoneType' object has no attribute 'chat'
 

2017-11-08 15:07:25.970043~ Traceback (most recent call last):
  File "D:\Phyton\bot\bot.py", line 797, in gogo
    bot.polling(none_stop=True)
  File "D:\Phyton\lib\site-packages\telebot\__init__.py", line 264, in polling
    self.__threaded_polling(none_stop, interval, timeout)
  File "D:\Phyton\lib\site-packages\telebot\__init__.py", line 288, in __threaded_polling
    self.worker_pool.raise_exceptions()
  File "D:\Phyton\lib\site-packages\telebot\util.py", line 107, in raise_exceptions
    six.reraise(self.exc_info[0], self.exc_info[1], self.exc_info[2])
  File "D:\Phyton\lib\site-packages\six.py", line 692, in reraise
    raise value.with_traceback(tb)
  File "D:\Phyton\lib\site-packages\telebot\util.py", line 58, in run
    task(*args, **kwargs)
  File "D:\Phyton\bot\decorators.py", line 33, in wrap
    func(message)
  File "D:\Phyton\bot\bot.py", line 369, in pas
    bot.register_next_step_handler(mess,logC)
  File "D:\Phyton\lib\site-packages\telebot\__init__.py", line 996, in register_next_step_handler
    chat_id = message.chat.id
AttributeError: 'NoneType' object has no attribute 'chat'
 

2017-11-08 15:07:30.981043~ Traceback (most recent call last):
  File "D:\Phyton\bot\bot.py", line 797, in gogo
    bot.polling(none_stop=True)
  File "D:\Phyton\lib\site-packages\telebot\__init__.py", line 264, in polling
    self.__threaded_polling(none_stop, interval, timeout)
  File "D:\Phyton\lib\site-packages\telebot\__init__.py", line 288, in __threaded_polling
    self.worker_pool.raise_exceptions()
  File "D:\Phyton\lib\site-packages\telebot\util.py", line 107, in raise_exceptions
    six.reraise(self.exc_info[0], self.exc_info[1], self.exc_info[2])
  File "D:\Phyton\lib\site-packages\six.py", line 692, in reraise
    raise value.with_traceback(tb)
  File "D:\Phyton\lib\site-packages\telebot\util.py", line 58, in run
    task(*args, **kwargs)
  File "D:\Phyton\bot\decorators.py", line 33, in wrap
    func(message)
  File "D:\Phyton\bot\bot.py", line 369, in pas
    bot.register_next_step_handler(mess,logC)
  File "D:\Phyton\lib\site-packages\telebot\__init__.py", line 996, in register_next_step_handler
    chat_id = message.chat.id
AttributeError: 'NoneType' object has no attribute 'chat'
 

2017-11-08 15:07:35.987043~ Traceback (most recent call last):
  File "D:\Phyton\bot\bot.py", line 797, in gogo
    bot.polling(none_stop=True)
  File "D:\Phyton\lib\site-packages\telebot\__init__.py", line 264, in polling
    self.__threaded_polling(none_stop, interval, timeout)
  File "D:\Phyton\lib\site-packages\telebot\__init__.py", line 288, in __threaded_polling
    self.worker_pool.raise_exceptions()
  File "D:\Phyton\lib\site-packages\telebot\util.py", line 107, in raise_exceptions
    six.reraise(self.exc_info[0], self.exc_info[1], self.exc_info[2])
  File "D:\Phyton\lib\site-packages\six.py", line 692, in reraise
    raise value.with_traceback(tb)
  File "D:\Phyton\lib\site-packages\telebot\util.py", line 58, in run
    task(*args, **kwargs)
  File "D:\Phyton\bot\decorators.py", line 33, in wrap
    func(message)
  File "D:\Phyton\bot\bot.py", line 369, in pas
    bot.register_next_step_handler(mess,logC)
  File "D:\Phyton\lib\site-packages\telebot\__init__.py", line 996, in register_next_step_handler
    chat_id = message.chat.id
AttributeError: 'NoneType' object has no attribute 'chat'
 

2017-11-08 15:07:40.993043~ Traceback (most recent call last):
  File "D:\Phyton\bot\bot.py", line 797, in gogo
    bot.polling(none_stop=True)
  File "D:\Phyton\lib\site-packages\telebot\__init__.py", line 264, in polling
    self.__threaded_polling(none_stop, interval, timeout)
  File "D:\Phyton\lib\site-packages\telebot\__init__.py", line 288, in __threaded_polling
    self.worker_pool.raise_exceptions()
  File "D:\Phyton\lib\site-packages\telebot\util.py", line 107, in raise_exceptions
    six.reraise(self.exc_info[0], self.exc_info[1], self.exc_info[2])
  File "D:\Phyton\lib\site-packages\six.py", line 692, in reraise
    raise value.with_traceback(tb)
  File "D:\Phyton\lib\site-packages\telebot\util.py", line 58, in run
    task(*args, **kwargs)
  File "D:\Phyton\bot\decorators.py", line 33, in wrap
    func(message)
  File "D:\Phyton\bot\bot.py", line 369, in pas
    bot.register_next_step_handler(mess,logC)
  File "D:\Phyton\lib\site-packages\telebot\__init__.py", line 996, in register_next_step_handler
    chat_id = message.chat.id
AttributeError: 'NoneType' object has no attribute 'chat'
 

2017-11-08 15:07:45.997043~ Traceback (most recent call last):
  File "D:\Phyton\bot\bot.py", line 797, in gogo
    bot.polling(none_stop=True)
  File "D:\Phyton\lib\site-packages\telebot\__init__.py", line 264, in polling
    self.__threaded_polling(none_stop, interval, timeout)
  File "D:\Phyton\lib\site-packages\telebot\__init__.py", line 288, in __threaded_polling
    self.worker_pool.raise_exceptions()
  File "D:\Phyton\lib\site-packages\telebot\util.py", line 107, in raise_exceptions
    six.reraise(self.exc_info[0], self.exc_info[1], self.exc_info[2])
  File "D:\Phyton\lib\site-packages\six.py", line 692, in reraise
    raise value.with_traceback(tb)
  File "D:\Phyton\lib\site-packages\telebot\util.py", line 58, in run
    task(*args, **kwargs)
  File "D:\Phyton\bot\decorators.py", line 33, in wrap
    func(message)
  File "D:\Phyton\bot\bot.py", line 369, in pas
    bot.register_next_step_handler(mess,logC)
  File "D:\Phyton\lib\site-packages\telebot\__init__.py", line 996, in register_next_step_handler
    chat_id = message.chat.id
AttributeError: 'NoneType' object has no attribute 'chat'
 

2017-11-08 15:07:51.001043~ Traceback (most recent call last):
  File "D:\Phyton\bot\bot.py", line 797, in gogo
    bot.polling(none_stop=True)
  File "D:\Phyton\lib\site-packages\telebot\__init__.py", line 264, in polling
    self.__threaded_polling(none_stop, interval, timeout)
  File "D:\Phyton\lib\site-packages\telebot\__init__.py", line 288, in __threaded_polling
    self.worker_pool.raise_exceptions()
  File "D:\Phyton\lib\site-packages\telebot\util.py", line 107, in raise_exceptions
    six.reraise(self.exc_info[0], self.exc_info[1], self.exc_info[2])
  File "D:\Phyton\lib\site-packages\six.py", line 692, in reraise
    raise value.with_traceback(tb)
  File "D:\Phyton\lib\site-packages\telebot\util.py", line 58, in run
    task(*args, **kwargs)
  File "D:\Phyton\bot\decorators.py", line 33, in wrap
    func(message)
  File "D:\Phyton\bot\bot.py", line 369, in pas
    bot.register_next_step_handler(mess,logC)
  File "D:\Phyton\lib\site-packages\telebot\__init__.py", line 996, in register_next_step_handler
    chat_id = message.chat.id
AttributeError: 'NoneType' object has no attribute 'chat'
 

2017-11-08 15:07:56.006043~ Traceback (most recent call last):
  File "D:\Phyton\bot\bot.py", line 797, in gogo
    bot.polling(none_stop=True)
  File "D:\Phyton\lib\site-packages\telebot\__init__.py", line 264, in polling
    self.__threaded_polling(none_stop, interval, timeout)
  File "D:\Phyton\lib\site-packages\telebot\__init__.py", line 288, in __threaded_polling
    self.worker_pool.raise_exceptions()
  File "D:\Phyton\lib\site-packages\telebot\util.py", line 107, in raise_exceptions
    six.reraise(self.exc_info[0], self.exc_info[1], self.exc_info[2])
  File "D:\Phyton\lib\site-packages\six.py", line 692, in reraise
    raise value.with_traceback(tb)
  File "D:\Phyton\lib\site-packages\telebot\util.py", line 58, in run
    task(*args, **kwargs)
  File "D:\Phyton\bot\decorators.py", line 33, in wrap
    func(message)
  File "D:\Phyton\bot\bot.py", line 369, in pas
    bot.register_next_step_handler(mess,logC)
  File "D:\Phyton\lib\site-packages\telebot\__init__.py", line 996, in register_next_step_handler
    chat_id = message.chat.id
AttributeError: 'NoneType' object has no attribute 'chat'
 

2017-11-08 15:08:01.010043~ Traceback (most recent call last):
  File "D:\Phyton\bot\bot.py", line 797, in gogo
    bot.polling(none_stop=True)
  File "D:\Phyton\lib\site-packages\telebot\__init__.py", line 264, in polling
    self.__threaded_polling(none_stop, interval, timeout)
  File "D:\Phyton\lib\site-packages\telebot\__init__.py", line 288, in __threaded_polling
    self.worker_pool.raise_exceptions()
  File "D:\Phyton\lib\site-packages\telebot\util.py", line 107, in raise_exceptions
    six.reraise(self.exc_info[0], self.exc_info[1], self.exc_info[2])
  File "D:\Phyton\lib\site-packages\six.py", line 692, in reraise
    raise value.with_traceback(tb)
  File "D:\Phyton\lib\site-packages\telebot\util.py", line 58, in run
    task(*args, **kwargs)
  File "D:\Phyton\bot\decorators.py", line 33, in wrap
    func(message)
  File "D:\Phyton\bot\bot.py", line 369, in pas
    bot.register_next_step_handler(mess,logC)
  File "D:\Phyton\lib\site-packages\telebot\__init__.py", line 996, in register_next_step_handler
    chat_id = message.chat.id
AttributeError: 'NoneType' object has no attribute 'chat'
 

2017-11-08 15:08:06.015043~ Traceback (most recent call last):
  File "D:\Phyton\bot\bot.py", line 797, in gogo
    bot.polling(none_stop=True)
  File "D:\Phyton\lib\site-packages\telebot\__init__.py", line 264, in polling
    self.__threaded_polling(none_stop, interval, timeout)
  File "D:\Phyton\lib\site-packages\telebot\__init__.py", line 288, in __threaded_polling
    self.worker_pool.raise_exceptions()
  File "D:\Phyton\lib\site-packages\telebot\util.py", line 107, in raise_exceptions
    six.reraise(self.exc_info[0], self.exc_info[1], self.exc_info[2])
  File "D:\Phyton\lib\site-packages\six.py", line 692, in reraise
    raise value.with_traceback(tb)
  File "D:\Phyton\lib\site-packages\telebot\util.py", line 58, in run
    task(*args, **kwargs)
  File "D:\Phyton\bot\decorators.py", line 33, in wrap
    func(message)
  File "D:\Phyton\bot\bot.py", line 369, in pas
    bot.register_next_step_handler(mess,logC)
  File "D:\Phyton\lib\site-packages\telebot\__init__.py", line 996, in register_next_step_handler
    chat_id = message.chat.id
AttributeError: 'NoneType' object has no attribute 'chat'
 

2017-11-08 15:08:11.020043~ Traceback (most recent call last):
  File "D:\Phyton\bot\bot.py", line 797, in gogo
    bot.polling(none_stop=True)
  File "D:\Phyton\lib\site-packages\telebot\__init__.py", line 264, in polling
    self.__threaded_polling(none_stop, interval, timeout)
  File "D:\Phyton\lib\site-packages\telebot\__init__.py", line 288, in __threaded_polling
    self.worker_pool.raise_exceptions()
  File "D:\Phyton\lib\site-packages\telebot\util.py", line 107, in raise_exceptions
    six.reraise(self.exc_info[0], self.exc_info[1], self.exc_info[2])
  File "D:\Phyton\lib\site-packages\six.py", line 692, in reraise
    raise value.with_traceback(tb)
  File "D:\Phyton\lib\site-packages\telebot\util.py", line 58, in run
    task(*args, **kwargs)
  File "D:\Phyton\bot\decorators.py", line 33, in wrap
    func(message)
  File "D:\Phyton\bot\bot.py", line 369, in pas
    bot.register_next_step_handler(mess,logC)
  File "D:\Phyton\lib\site-packages\telebot\__init__.py", line 996, in register_next_step_handler
    chat_id = message.chat.id
AttributeError: 'NoneType' object has no attribute 'chat'
 

2017-11-08 15:08:16.025043~ Traceback (most recent call last):
  File "D:\Phyton\bot\bot.py", line 797, in gogo
    bot.polling(none_stop=True)
  File "D:\Phyton\lib\site-packages\telebot\__init__.py", line 264, in polling
    self.__threaded_polling(none_stop, interval, timeout)
  File "D:\Phyton\lib\site-packages\telebot\__init__.py", line 288, in __threaded_polling
    self.worker_pool.raise_exceptions()
  File "D:\Phyton\lib\site-packages\telebot\util.py", line 107, in raise_exceptions
    six.reraise(self.exc_info[0], self.exc_info[1], self.exc_info[2])
  File "D:\Phyton\lib\site-packages\six.py", line 692, in reraise
    raise value.with_traceback(tb)
  File "D:\Phyton\lib\site-packages\telebot\util.py", line 58, in run
    task(*args, **kwargs)
  File "D:\Phyton\bot\decorators.py", line 33, in wrap
    func(message)
  File "D:\Phyton\bot\bot.py", line 369, in pas
    bot.register_next_step_handler(mess,logC)
  File "D:\Phyton\lib\site-packages\telebot\__init__.py", line 996, in register_next_step_handler
    chat_id = message.chat.id
AttributeError: 'NoneType' object has no attribute 'chat'
 

2017-11-08 15:08:21.030043~ Traceback (most recent call last):
  File "D:\Phyton\bot\bot.py", line 797, in gogo
    bot.polling(none_stop=True)
  File "D:\Phyton\lib\site-packages\telebot\__init__.py", line 264, in polling
    self.__threaded_polling(none_stop, interval, timeout)
  File "D:\Phyton\lib\site-packages\telebot\__init__.py", line 288, in __threaded_polling
    self.worker_pool.raise_exceptions()
  File "D:\Phyton\lib\site-packages\telebot\util.py", line 107, in raise_exceptions
    six.reraise(self.exc_info[0], self.exc_info[1], self.exc_info[2])
  File "D:\Phyton\lib\site-packages\six.py", line 692, in reraise
    raise value.with_traceback(tb)
  File "D:\Phyton\lib\site-packages\telebot\util.py", line 58, in run
    task(*args, **kwargs)
  File "D:\Phyton\bot\decorators.py", line 33, in wrap
    func(message)
  File "D:\Phyton\bot\bot.py", line 369, in pas
    bot.register_next_step_handler(mess,logC)
  File "D:\Phyton\lib\site-packages\telebot\__init__.py", line 996, in register_next_step_handler
    chat_id = message.chat.id
AttributeError: 'NoneType' object has no attribute 'chat'
 

2017-11-08 15:08:26.033043~ Traceback (most recent call last):
  File "D:\Phyton\bot\bot.py", line 797, in gogo
    bot.polling(none_stop=True)
  File "D:\Phyton\lib\site-packages\telebot\__init__.py", line 264, in polling
    self.__threaded_polling(none_stop, interval, timeout)
  File "D:\Phyton\lib\site-packages\telebot\__init__.py", line 288, in __threaded_polling
    self.worker_pool.raise_exceptions()
  File "D:\Phyton\lib\site-packages\telebot\util.py", line 107, in raise_exceptions
    six.reraise(self.exc_info[0], self.exc_info[1], self.exc_info[2])
  File "D:\Phyton\lib\site-packages\six.py", line 692, in reraise
    raise value.with_traceback(tb)
  File "D:\Phyton\lib\site-packages\telebot\util.py", line 58, in run
    task(*args, **kwargs)
  File "D:\Phyton\bot\decorators.py", line 33, in wrap
    func(message)
  File "D:\Phyton\bot\bot.py", line 369, in pas
    bot.register_next_step_handler(mess,logC)
  File "D:\Phyton\lib\site-packages\telebot\__init__.py", line 996, in register_next_step_handler
    chat_id = message.chat.id
AttributeError: 'NoneType' object has no attribute 'chat'
 

2017-11-08 15:08:31.040043~ Traceback (most recent call last):
  File "D:\Phyton\bot\bot.py", line 797, in gogo
    bot.polling(none_stop=True)
  File "D:\Phyton\lib\site-packages\telebot\__init__.py", line 264, in polling
    self.__threaded_polling(none_stop, interval, timeout)
  File "D:\Phyton\lib\site-packages\telebot\__init__.py", line 288, in __threaded_polling
    self.worker_pool.raise_exceptions()
  File "D:\Phyton\lib\site-packages\telebot\util.py", line 107, in raise_exceptions
    six.reraise(self.exc_info[0], self.exc_info[1], self.exc_info[2])
  File "D:\Phyton\lib\site-packages\six.py", line 692, in reraise
    raise value.with_traceback(tb)
  File "D:\Phyton\lib\site-packages\telebot\util.py", line 58, in run
    task(*args, **kwargs)
  File "D:\Phyton\bot\decorators.py", line 33, in wrap
    func(message)
  File "D:\Phyton\bot\bot.py", line 369, in pas
    bot.register_next_step_handler(mess,logC)
  File "D:\Phyton\lib\site-packages\telebot\__init__.py", line 996, in register_next_step_handler
    chat_id = message.chat.id
AttributeError: 'NoneType' object has no attribute 'chat'
 

2017-11-08 15:08:36.045043~ Traceback (most recent call last):
  File "D:\Phyton\bot\bot.py", line 797, in gogo
    bot.polling(none_stop=True)
  File "D:\Phyton\lib\site-packages\telebot\__init__.py", line 264, in polling
    self.__threaded_polling(none_stop, interval, timeout)
  File "D:\Phyton\lib\site-packages\telebot\__init__.py", line 288, in __threaded_polling
    self.worker_pool.raise_exceptions()
  File "D:\Phyton\lib\site-packages\telebot\util.py", line 107, in raise_exceptions
    six.reraise(self.exc_info[0], self.exc_info[1], self.exc_info[2])
  File "D:\Phyton\lib\site-packages\six.py", line 692, in reraise
    raise value.with_traceback(tb)
  File "D:\Phyton\lib\site-packages\telebot\util.py", line 58, in run
    task(*args, **kwargs)
  File "D:\Phyton\bot\decorators.py", line 33, in wrap
    func(message)
  File "D:\Phyton\bot\bot.py", line 369, in pas
    bot.register_next_step_handler(mess,logC)
  File "D:\Phyton\lib\site-packages\telebot\__init__.py", line 996, in register_next_step_handler
    chat_id = message.chat.id
AttributeError: 'NoneType' object has no attribute 'chat'
 

2017-11-08 15:08:41.050043~ Traceback (most recent call last):
  File "D:\Phyton\bot\bot.py", line 797, in gogo
    bot.polling(none_stop=True)
  File "D:\Phyton\lib\site-packages\telebot\__init__.py", line 264, in polling
    self.__threaded_polling(none_stop, interval, timeout)
  File "D:\Phyton\lib\site-packages\telebot\__init__.py", line 288, in __threaded_polling
    self.worker_pool.raise_exceptions()
  File "D:\Phyton\lib\site-packages\telebot\util.py", line 107, in raise_exceptions
    six.reraise(self.exc_info[0], self.exc_info[1], self.exc_info[2])
  File "D:\Phyton\lib\site-packages\six.py", line 692, in reraise
    raise value.with_traceback(tb)
  File "D:\Phyton\lib\site-packages\telebot\util.py", line 58, in run
    task(*args, **kwargs)
  File "D:\Phyton\bot\decorators.py", line 33, in wrap
    func(message)
  File "D:\Phyton\bot\bot.py", line 369, in pas
    bot.register_next_step_handler(mess,logC)
  File "D:\Phyton\lib\site-packages\telebot\__init__.py", line 996, in register_next_step_handler
    chat_id = message.chat.id
AttributeError: 'NoneType' object has no attribute 'chat'
 

2017-11-08 15:08:46.055043~ Traceback (most recent call last):
  File "D:\Phyton\bot\bot.py", line 797, in gogo
    bot.polling(none_stop=True)
  File "D:\Phyton\lib\site-packages\telebot\__init__.py", line 264, in polling
    self.__threaded_polling(none_stop, interval, timeout)
  File "D:\Phyton\lib\site-packages\telebot\__init__.py", line 288, in __threaded_polling
    self.worker_pool.raise_exceptions()
  File "D:\Phyton\lib\site-packages\telebot\util.py", line 107, in raise_exceptions
    six.reraise(self.exc_info[0], self.exc_info[1], self.exc_info[2])
  File "D:\Phyton\lib\site-packages\six.py", line 692, in reraise
    raise value.with_traceback(tb)
  File "D:\Phyton\lib\site-packages\telebot\util.py", line 58, in run
    task(*args, **kwargs)
  File "D:\Phyton\bot\decorators.py", line 33, in wrap
    func(message)
  File "D:\Phyton\bot\bot.py", line 369, in pas
    bot.register_next_step_handler(mess,logC)
  File "D:\Phyton\lib\site-packages\telebot\__init__.py", line 996, in register_next_step_handler
    chat_id = message.chat.id
AttributeError: 'NoneType' object has no attribute 'chat'
 

2017-11-08 15:08:51.065043~ Traceback (most recent call last):
  File "D:\Phyton\bot\bot.py", line 797, in gogo
    bot.polling(none_stop=True)
  File "D:\Phyton\lib\site-packages\telebot\__init__.py", line 264, in polling
    self.__threaded_polling(none_stop, interval, timeout)
  File "D:\Phyton\lib\site-packages\telebot\__init__.py", line 288, in __threaded_polling
    self.worker_pool.raise_exceptions()
  File "D:\Phyton\lib\site-packages\telebot\util.py", line 107, in raise_exceptions
    six.reraise(self.exc_info[0], self.exc_info[1], self.exc_info[2])
  File "D:\Phyton\lib\site-packages\six.py", line 692, in reraise
    raise value.with_traceback(tb)
  File "D:\Phyton\lib\site-packages\telebot\util.py", line 58, in run
    task(*args, **kwargs)
  File "D:\Phyton\bot\decorators.py", line 33, in wrap
    func(message)
  File "D:\Phyton\bot\bot.py", line 369, in pas
    bot.register_next_step_handler(mess,logC)
  File "D:\Phyton\lib\site-packages\telebot\__init__.py", line 996, in register_next_step_handler
    chat_id = message.chat.id
AttributeError: 'NoneType' object has no attribute 'chat'
 

2017-11-08 15:08:56.070043~ Traceback (most recent call last):
  File "D:\Phyton\bot\bot.py", line 797, in gogo
    bot.polling(none_stop=True)
  File "D:\Phyton\lib\site-packages\telebot\__init__.py", line 264, in polling
    self.__threaded_polling(none_stop, interval, timeout)
  File "D:\Phyton\lib\site-packages\telebot\__init__.py", line 288, in __threaded_polling
    self.worker_pool.raise_exceptions()
  File "D:\Phyton\lib\site-packages\telebot\util.py", line 107, in raise_exceptions
    six.reraise(self.exc_info[0], self.exc_info[1], self.exc_info[2])
  File "D:\Phyton\lib\site-packages\six.py", line 692, in reraise
    raise value.with_traceback(tb)
  File "D:\Phyton\lib\site-packages\telebot\util.py", line 58, in run
    task(*args, **kwargs)
  File "D:\Phyton\bot\decorators.py", line 33, in wrap
    func(message)
  File "D:\Phyton\bot\bot.py", line 369, in pas
    bot.register_next_step_handler(mess,logC)
  File "D:\Phyton\lib\site-packages\telebot\__init__.py", line 996, in register_next_step_handler
    chat_id = message.chat.id
AttributeError: 'NoneType' object has no attribute 'chat'
 

2017-11-08 15:09:01.075043~ Traceback (most recent call last):
  File "D:\Phyton\bot\bot.py", line 797, in gogo
    bot.polling(none_stop=True)
  File "D:\Phyton\lib\site-packages\telebot\__init__.py", line 264, in polling
    self.__threaded_polling(none_stop, interval, timeout)
  File "D:\Phyton\lib\site-packages\telebot\__init__.py", line 288, in __threaded_polling
    self.worker_pool.raise_exceptions()
  File "D:\Phyton\lib\site-packages\telebot\util.py", line 107, in raise_exceptions
    six.reraise(self.exc_info[0], self.exc_info[1], self.exc_info[2])
  File "D:\Phyton\lib\site-packages\six.py", line 692, in reraise
    raise value.with_traceback(tb)
  File "D:\Phyton\lib\site-packages\telebot\util.py", line 58, in run
    task(*args, **kwargs)
  File "D:\Phyton\bot\decorators.py", line 33, in wrap
    func(message)
  File "D:\Phyton\bot\bot.py", line 369, in pas
    bot.register_next_step_handler(mess,logC)
  File "D:\Phyton\lib\site-packages\telebot\__init__.py", line 996, in register_next_step_handler
    chat_id = message.chat.id
AttributeError: 'NoneType' object has no attribute 'chat'
 

2017-11-08 15:09:06.080043~ Traceback (most recent call last):
  File "D:\Phyton\bot\bot.py", line 797, in gogo
    bot.polling(none_stop=True)
  File "D:\Phyton\lib\site-packages\telebot\__init__.py", line 264, in polling
    self.__threaded_polling(none_stop, interval, timeout)
  File "D:\Phyton\lib\site-packages\telebot\__init__.py", line 288, in __threaded_polling
    self.worker_pool.raise_exceptions()
  File "D:\Phyton\lib\site-packages\telebot\util.py", line 107, in raise_exceptions
    six.reraise(self.exc_info[0], self.exc_info[1], self.exc_info[2])
  File "D:\Phyton\lib\site-packages\six.py", line 692, in reraise
    raise value.with_traceback(tb)
  File "D:\Phyton\lib\site-packages\telebot\util.py", line 58, in run
    task(*args, **kwargs)
  File "D:\Phyton\bot\decorators.py", line 33, in wrap
    func(message)
  File "D:\Phyton\bot\bot.py", line 369, in pas
    bot.register_next_step_handler(mess,logC)
  File "D:\Phyton\lib\site-packages\telebot\__init__.py", line 996, in register_next_step_handler
    chat_id = message.chat.id
AttributeError: 'NoneType' object has no attribute 'chat'
 

2017-11-08 15:09:11.085043~ Traceback (most recent call last):
  File "D:\Phyton\bot\bot.py", line 797, in gogo
    bot.polling(none_stop=True)
  File "D:\Phyton\lib\site-packages\telebot\__init__.py", line 264, in polling
    self.__threaded_polling(none_stop, interval, timeout)
  File "D:\Phyton\lib\site-packages\telebot\__init__.py", line 288, in __threaded_polling
    self.worker_pool.raise_exceptions()
  File "D:\Phyton\lib\site-packages\telebot\util.py", line 107, in raise_exceptions
    six.reraise(self.exc_info[0], self.exc_info[1], self.exc_info[2])
  File "D:\Phyton\lib\site-packages\six.py", line 692, in reraise
    raise value.with_traceback(tb)
  File "D:\Phyton\lib\site-packages\telebot\util.py", line 58, in run
    task(*args, **kwargs)
  File "D:\Phyton\bot\decorators.py", line 33, in wrap
    func(message)
  File "D:\Phyton\bot\bot.py", line 369, in pas
    bot.register_next_step_handler(mess,logC)
  File "D:\Phyton\lib\site-packages\telebot\__init__.py", line 996, in register_next_step_handler
    chat_id = message.chat.id
AttributeError: 'NoneType' object has no attribute 'chat'
 

2017-11-08 15:09:16.090043~ Traceback (most recent call last):
  File "D:\Phyton\bot\bot.py", line 797, in gogo
    bot.polling(none_stop=True)
  File "D:\Phyton\lib\site-packages\telebot\__init__.py", line 264, in polling
    self.__threaded_polling(none_stop, interval, timeout)
  File "D:\Phyton\lib\site-packages\telebot\__init__.py", line 288, in __threaded_polling
    self.worker_pool.raise_exceptions()
  File "D:\Phyton\lib\site-packages\telebot\util.py", line 107, in raise_exceptions
    six.reraise(self.exc_info[0], self.exc_info[1], self.exc_info[2])
  File "D:\Phyton\lib\site-packages\six.py", line 692, in reraise
    raise value.with_traceback(tb)
  File "D:\Phyton\lib\site-packages\telebot\util.py", line 58, in run
    task(*args, **kwargs)
  File "D:\Phyton\bot\decorators.py", line 33, in wrap
    func(message)
  File "D:\Phyton\bot\bot.py", line 369, in pas
    bot.register_next_step_handler(mess,logC)
  File "D:\Phyton\lib\site-packages\telebot\__init__.py", line 996, in register_next_step_handler
    chat_id = message.chat.id
AttributeError: 'NoneType' object has no attribute 'chat'
 

2017-11-08 15:09:21.095043~ Traceback (most recent call last):
  File "D:\Phyton\bot\bot.py", line 797, in gogo
    bot.polling(none_stop=True)
  File "D:\Phyton\lib\site-packages\telebot\__init__.py", line 264, in polling
    self.__threaded_polling(none_stop, interval, timeout)
  File "D:\Phyton\lib\site-packages\telebot\__init__.py", line 288, in __threaded_polling
    self.worker_pool.raise_exceptions()
  File "D:\Phyton\lib\site-packages\telebot\util.py", line 107, in raise_exceptions
    six.reraise(self.exc_info[0], self.exc_info[1], self.exc_info[2])
  File "D:\Phyton\lib\site-packages\six.py", line 692, in reraise
    raise value.with_traceback(tb)
  File "D:\Phyton\lib\site-packages\telebot\util.py", line 58, in run
    task(*args, **kwargs)
  File "D:\Phyton\bot\decorators.py", line 33, in wrap
    func(message)
  File "D:\Phyton\bot\bot.py", line 369, in pas
    bot.register_next_step_handler(mess,logC)
  File "D:\Phyton\lib\site-packages\telebot\__init__.py", line 996, in register_next_step_handler
    chat_id = message.chat.id
AttributeError: 'NoneType' object has no attribute 'chat'
 

2017-11-08 15:09:26.100043~ Traceback (most recent call last):
  File "D:\Phyton\bot\bot.py", line 797, in gogo
    bot.polling(none_stop=True)
  File "D:\Phyton\lib\site-packages\telebot\__init__.py", line 264, in polling
    self.__threaded_polling(none_stop, interval, timeout)
  File "D:\Phyton\lib\site-packages\telebot\__init__.py", line 288, in __threaded_polling
    self.worker_pool.raise_exceptions()
  File "D:\Phyton\lib\site-packages\telebot\util.py", line 107, in raise_exceptions
    six.reraise(self.exc_info[0], self.exc_info[1], self.exc_info[2])
  File "D:\Phyton\lib\site-packages\six.py", line 692, in reraise
    raise value.with_traceback(tb)
  File "D:\Phyton\lib\site-packages\telebot\util.py", line 58, in run
    task(*args, **kwargs)
  File "D:\Phyton\bot\decorators.py", line 33, in wrap
    func(message)
  File "D:\Phyton\bot\bot.py", line 369, in pas
    bot.register_next_step_handler(mess,logC)
  File "D:\Phyton\lib\site-packages\telebot\__init__.py", line 996, in register_next_step_handler
    chat_id = message.chat.id
AttributeError: 'NoneType' object has no attribute 'chat'
 

2017-11-08 15:09:31.103043~ Traceback (most recent call last):
  File "D:\Phyton\bot\bot.py", line 797, in gogo
    bot.polling(none_stop=True)
  File "D:\Phyton\lib\site-packages\telebot\__init__.py", line 264, in polling
    self.__threaded_polling(none_stop, interval, timeout)
  File "D:\Phyton\lib\site-packages\telebot\__init__.py", line 288, in __threaded_polling
    self.worker_pool.raise_exceptions()
  File "D:\Phyton\lib\site-packages\telebot\util.py", line 107, in raise_exceptions
    six.reraise(self.exc_info[0], self.exc_info[1], self.exc_info[2])
  File "D:\Phyton\lib\site-packages\six.py", line 692, in reraise
    raise value.with_traceback(tb)
  File "D:\Phyton\lib\site-packages\telebot\util.py", line 58, in run
    task(*args, **kwargs)
  File "D:\Phyton\bot\decorators.py", line 33, in wrap
    func(message)
  File "D:\Phyton\bot\bot.py", line 369, in pas
    bot.register_next_step_handler(mess,logC)
  File "D:\Phyton\lib\site-packages\telebot\__init__.py", line 996, in register_next_step_handler
    chat_id = message.chat.id
AttributeError: 'NoneType' object has no attribute 'chat'
 

2017-11-08 15:09:36.110043~ Traceback (most recent call last):
  File "D:\Phyton\bot\bot.py", line 797, in gogo
    bot.polling(none_stop=True)
  File "D:\Phyton\lib\site-packages\telebot\__init__.py", line 264, in polling
    self.__threaded_polling(none_stop, interval, timeout)
  File "D:\Phyton\lib\site-packages\telebot\__init__.py", line 288, in __threaded_polling
    self.worker_pool.raise_exceptions()
  File "D:\Phyton\lib\site-packages\telebot\util.py", line 107, in raise_exceptions
    six.reraise(self.exc_info[0], self.exc_info[1], self.exc_info[2])
  File "D:\Phyton\lib\site-packages\six.py", line 692, in reraise
    raise value.with_traceback(tb)
  File "D:\Phyton\lib\site-packages\telebot\util.py", line 58, in run
    task(*args, **kwargs)
  File "D:\Phyton\bot\decorators.py", line 33, in wrap
    func(message)
  File "D:\Phyton\bot\bot.py", line 369, in pas
    bot.register_next_step_handler(mess,logC)
  File "D:\Phyton\lib\site-packages\telebot\__init__.py", line 996, in register_next_step_handler
    chat_id = message.chat.id
AttributeError: 'NoneType' object has no attribute 'chat'
 

2017-11-08 15:09:41.169043~ Traceback (most recent call last):
  File "D:\Phyton\bot\bot.py", line 797, in gogo
    bot.polling(none_stop=True)
  File "D:\Phyton\lib\site-packages\telebot\__init__.py", line 264, in polling
    self.__threaded_polling(none_stop, interval, timeout)
  File "D:\Phyton\lib\site-packages\telebot\__init__.py", line 288, in __threaded_polling
    self.worker_pool.raise_exceptions()
  File "D:\Phyton\lib\site-packages\telebot\util.py", line 107, in raise_exceptions
    six.reraise(self.exc_info[0], self.exc_info[1], self.exc_info[2])
  File "D:\Phyton\lib\site-packages\six.py", line 692, in reraise
    raise value.with_traceback(tb)
  File "D:\Phyton\lib\site-packages\telebot\util.py", line 58, in run
    task(*args, **kwargs)
  File "D:\Phyton\bot\decorators.py", line 33, in wrap
    func(message)
  File "D:\Phyton\bot\bot.py", line 369, in pas
    bot.register_next_step_handler(mess,logC)
  File "D:\Phyton\lib\site-packages\telebot\__init__.py", line 996, in register_next_step_handler
    chat_id = message.chat.id
AttributeError: 'NoneType' object has no attribute 'chat'
 

2017-11-08 15:09:46.173043~ Traceback (most recent call last):
  File "D:\Phyton\bot\bot.py", line 797, in gogo
    bot.polling(none_stop=True)
  File "D:\Phyton\lib\site-packages\telebot\__init__.py", line 264, in polling
    self.__threaded_polling(none_stop, interval, timeout)
  File "D:\Phyton\lib\site-packages\telebot\__init__.py", line 288, in __threaded_polling
    self.worker_pool.raise_exceptions()
  File "D:\Phyton\lib\site-packages\telebot\util.py", line 107, in raise_exceptions
    six.reraise(self.exc_info[0], self.exc_info[1], self.exc_info[2])
  File "D:\Phyton\lib\site-packages\six.py", line 692, in reraise
    raise value.with_traceback(tb)
  File "D:\Phyton\lib\site-packages\telebot\util.py", line 58, in run
    task(*args, **kwargs)
  File "D:\Phyton\bot\decorators.py", line 33, in wrap
    func(message)
  File "D:\Phyton\bot\bot.py", line 369, in pas
    bot.register_next_step_handler(mess,logC)
  File "D:\Phyton\lib\site-packages\telebot\__init__.py", line 996, in register_next_step_handler
    chat_id = message.chat.id
AttributeError: 'NoneType' object has no attribute 'chat'
 

2017-11-08 15:09:51.177043~ Traceback (most recent call last):
  File "D:\Phyton\bot\bot.py", line 797, in gogo
    bot.polling(none_stop=True)
  File "D:\Phyton\lib\site-packages\telebot\__init__.py", line 264, in polling
    self.__threaded_polling(none_stop, interval, timeout)
  File "D:\Phyton\lib\site-packages\telebot\__init__.py", line 288, in __threaded_polling
    self.worker_pool.raise_exceptions()
  File "D:\Phyton\lib\site-packages\telebot\util.py", line 107, in raise_exceptions
    six.reraise(self.exc_info[0], self.exc_info[1], self.exc_info[2])
  File "D:\Phyton\lib\site-packages\six.py", line 692, in reraise
    raise value.with_traceback(tb)
  File "D:\Phyton\lib\site-packages\telebot\util.py", line 58, in run
    task(*args, **kwargs)
  File "D:\Phyton\bot\decorators.py", line 33, in wrap
    func(message)
  File "D:\Phyton\bot\bot.py", line 369, in pas
    bot.register_next_step_handler(mess,logC)
  File "D:\Phyton\lib\site-packages\telebot\__init__.py", line 996, in register_next_step_handler
    chat_id = message.chat.id
AttributeError: 'NoneType' object has no attribute 'chat'
 

2017-11-08 15:09:56.183043~ Traceback (most recent call last):
  File "D:\Phyton\bot\bot.py", line 797, in gogo
    bot.polling(none_stop=True)
  File "D:\Phyton\lib\site-packages\telebot\__init__.py", line 264, in polling
    self.__threaded_polling(none_stop, interval, timeout)
  File "D:\Phyton\lib\site-packages\telebot\__init__.py", line 288, in __threaded_polling
    self.worker_pool.raise_exceptions()
  File "D:\Phyton\lib\site-packages\telebot\util.py", line 107, in raise_exceptions
    six.reraise(self.exc_info[0], self.exc_info[1], self.exc_info[2])
  File "D:\Phyton\lib\site-packages\six.py", line 692, in reraise
    raise value.with_traceback(tb)
  File "D:\Phyton\lib\site-packages\telebot\util.py", line 58, in run
    task(*args, **kwargs)
  File "D:\Phyton\bot\decorators.py", line 33, in wrap
    func(message)
  File "D:\Phyton\bot\bot.py", line 369, in pas
    bot.register_next_step_handler(mess,logC)
  File "D:\Phyton\lib\site-packages\telebot\__init__.py", line 996, in register_next_step_handler
    chat_id = message.chat.id
AttributeError: 'NoneType' object has no attribute 'chat'
 

2017-11-08 15:10:01.186043~ Traceback (most recent call last):
  File "D:\Phyton\bot\bot.py", line 797, in gogo
    bot.polling(none_stop=True)
  File "D:\Phyton\lib\site-packages\telebot\__init__.py", line 264, in polling
    self.__threaded_polling(none_stop, interval, timeout)
  File "D:\Phyton\lib\site-packages\telebot\__init__.py", line 288, in __threaded_polling
    self.worker_pool.raise_exceptions()
  File "D:\Phyton\lib\site-packages\telebot\util.py", line 107, in raise_exceptions
    six.reraise(self.exc_info[0], self.exc_info[1], self.exc_info[2])
  File "D:\Phyton\lib\site-packages\six.py", line 692, in reraise
    raise value.with_traceback(tb)
  File "D:\Phyton\lib\site-packages\telebot\util.py", line 58, in run
    task(*args, **kwargs)
  File "D:\Phyton\bot\decorators.py", line 33, in wrap
    func(message)
  File "D:\Phyton\bot\bot.py", line 369, in pas
    bot.register_next_step_handler(mess,logC)
  File "D:\Phyton\lib\site-packages\telebot\__init__.py", line 996, in register_next_step_handler
    chat_id = message.chat.id
AttributeError: 'NoneType' object has no attribute 'chat'
 

2017-11-08 15:10:06.190043~ Traceback (most recent call last):
  File "D:\Phyton\bot\bot.py", line 797, in gogo
    bot.polling(none_stop=True)
  File "D:\Phyton\lib\site-packages\telebot\__init__.py", line 264, in polling
    self.__threaded_polling(none_stop, interval, timeout)
  File "D:\Phyton\lib\site-packages\telebot\__init__.py", line 288, in __threaded_polling
    self.worker_pool.raise_exceptions()
  File "D:\Phyton\lib\site-packages\telebot\util.py", line 107, in raise_exceptions
    six.reraise(self.exc_info[0], self.exc_info[1], self.exc_info[2])
  File "D:\Phyton\lib\site-packages\six.py", line 692, in reraise
    raise value.with_traceback(tb)
  File "D:\Phyton\lib\site-packages\telebot\util.py", line 58, in run
    task(*args, **kwargs)
  File "D:\Phyton\bot\decorators.py", line 33, in wrap
    func(message)
  File "D:\Phyton\bot\bot.py", line 369, in pas
    bot.register_next_step_handler(mess,logC)
  File "D:\Phyton\lib\site-packages\telebot\__init__.py", line 996, in register_next_step_handler
    chat_id = message.chat.id
AttributeError: 'NoneType' object has no attribute 'chat'
 

2017-11-08 15:10:11.216043~ Traceback (most recent call last):
  File "D:\Phyton\bot\bot.py", line 797, in gogo
    bot.polling(none_stop=True)
  File "D:\Phyton\lib\site-packages\telebot\__init__.py", line 264, in polling
    self.__threaded_polling(none_stop, interval, timeout)
  File "D:\Phyton\lib\site-packages\telebot\__init__.py", line 288, in __threaded_polling
    self.worker_pool.raise_exceptions()
  File "D:\Phyton\lib\site-packages\telebot\util.py", line 107, in raise_exceptions
    six.reraise(self.exc_info[0], self.exc_info[1], self.exc_info[2])
  File "D:\Phyton\lib\site-packages\six.py", line 692, in reraise
    raise value.with_traceback(tb)
  File "D:\Phyton\lib\site-packages\telebot\util.py", line 58, in run
    task(*args, **kwargs)
  File "D:\Phyton\bot\decorators.py", line 33, in wrap
    func(message)
  File "D:\Phyton\bot\bot.py", line 369, in pas
    bot.register_next_step_handler(mess,logC)
  File "D:\Phyton\lib\site-packages\telebot\__init__.py", line 996, in register_next_step_handler
    chat_id = message.chat.id
AttributeError: 'NoneType' object has no attribute 'chat'
 

2017-11-08 15:10:16.222043~ Traceback (most recent call last):
  File "D:\Phyton\bot\bot.py", line 797, in gogo
    bot.polling(none_stop=True)
  File "D:\Phyton\lib\site-packages\telebot\__init__.py", line 264, in polling
    self.__threaded_polling(none_stop, interval, timeout)
  File "D:\Phyton\lib\site-packages\telebot\__init__.py", line 288, in __threaded_polling
    self.worker_pool.raise_exceptions()
  File "D:\Phyton\lib\site-packages\telebot\util.py", line 107, in raise_exceptions
    six.reraise(self.exc_info[0], self.exc_info[1], self.exc_info[2])
  File "D:\Phyton\lib\site-packages\six.py", line 692, in reraise
    raise value.with_traceback(tb)
  File "D:\Phyton\lib\site-packages\telebot\util.py", line 58, in run
    task(*args, **kwargs)
  File "D:\Phyton\bot\decorators.py", line 33, in wrap
    func(message)
  File "D:\Phyton\bot\bot.py", line 369, in pas
    bot.register_next_step_handler(mess,logC)
  File "D:\Phyton\lib\site-packages\telebot\__init__.py", line 996, in register_next_step_handler
    chat_id = message.chat.id
AttributeError: 'NoneType' object has no attribute 'chat'
 

2017-11-08 15:10:21.226043~ Traceback (most recent call last):
  File "D:\Phyton\bot\bot.py", line 797, in gogo
    bot.polling(none_stop=True)
  File "D:\Phyton\lib\site-packages\telebot\__init__.py", line 264, in polling
    self.__threaded_polling(none_stop, interval, timeout)
  File "D:\Phyton\lib\site-packages\telebot\__init__.py", line 288, in __threaded_polling
    self.worker_pool.raise_exceptions()
  File "D:\Phyton\lib\site-packages\telebot\util.py", line 107, in raise_exceptions
    six.reraise(self.exc_info[0], self.exc_info[1], self.exc_info[2])
  File "D:\Phyton\lib\site-packages\six.py", line 692, in reraise
    raise value.with_traceback(tb)
  File "D:\Phyton\lib\site-packages\telebot\util.py", line 58, in run
    task(*args, **kwargs)
  File "D:\Phyton\bot\decorators.py", line 33, in wrap
    func(message)
  File "D:\Phyton\bot\bot.py", line 369, in pas
    bot.register_next_step_handler(mess,logC)
  File "D:\Phyton\lib\site-packages\telebot\__init__.py", line 996, in register_next_step_handler
    chat_id = message.chat.id
AttributeError: 'NoneType' object has no attribute 'chat'
 

2017-11-08 15:10:26.229043~ Traceback (most recent call last):
  File "D:\Phyton\bot\bot.py", line 797, in gogo
    bot.polling(none_stop=True)
  File "D:\Phyton\lib\site-packages\telebot\__init__.py", line 264, in polling
    self.__threaded_polling(none_stop, interval, timeout)
  File "D:\Phyton\lib\site-packages\telebot\__init__.py", line 288, in __threaded_polling
    self.worker_pool.raise_exceptions()
  File "D:\Phyton\lib\site-packages\telebot\util.py", line 107, in raise_exceptions
    six.reraise(self.exc_info[0], self.exc_info[1], self.exc_info[2])
  File "D:\Phyton\lib\site-packages\six.py", line 692, in reraise
    raise value.with_traceback(tb)
  File "D:\Phyton\lib\site-packages\telebot\util.py", line 58, in run
    task(*args, **kwargs)
  File "D:\Phyton\bot\decorators.py", line 33, in wrap
    func(message)
  File "D:\Phyton\bot\bot.py", line 369, in pas
    bot.register_next_step_handler(mess,logC)
  File "D:\Phyton\lib\site-packages\telebot\__init__.py", line 996, in register_next_step_handler
    chat_id = message.chat.id
AttributeError: 'NoneType' object has no attribute 'chat'
 

2017-11-08 15:10:31.232043~ Traceback (most recent call last):
  File "D:\Phyton\bot\bot.py", line 797, in gogo
    bot.polling(none_stop=True)
  File "D:\Phyton\lib\site-packages\telebot\__init__.py", line 264, in polling
    self.__threaded_polling(none_stop, interval, timeout)
  File "D:\Phyton\lib\site-packages\telebot\__init__.py", line 288, in __threaded_polling
    self.worker_pool.raise_exceptions()
  File "D:\Phyton\lib\site-packages\telebot\util.py", line 107, in raise_exceptions
    six.reraise(self.exc_info[0], self.exc_info[1], self.exc_info[2])
  File "D:\Phyton\lib\site-packages\six.py", line 692, in reraise
    raise value.with_traceback(tb)
  File "D:\Phyton\lib\site-packages\telebot\util.py", line 58, in run
    task(*args, **kwargs)
  File "D:\Phyton\bot\decorators.py", line 33, in wrap
    func(message)
  File "D:\Phyton\bot\bot.py", line 369, in pas
    bot.register_next_step_handler(mess,logC)
  File "D:\Phyton\lib\site-packages\telebot\__init__.py", line 996, in register_next_step_handler
    chat_id = message.chat.id
AttributeError: 'NoneType' object has no attribute 'chat'
 

2017-11-08 15:10:47.354043~ Traceback (most recent call last):
  File "D:\Phyton\bot\decorators.py", line 10, in wrap
    func(*args,**kargs)
  File "D:\Phyton\bot\decorators.py", line 33, in wrap
    func(message)
  File "D:\Phyton\bot\bot.py", line 406, in choiceCard
    mess=balance3(card[0][1],card[0][1])
TypeError: balance3() missing 2 required positional arguments: 'keyboard' and 'message'
 

2017-11-08 15:13:07.170043~ Traceback (most recent call last):
  File "D:\Phyton\bot\decorators.py", line 10, in wrap
    func(*args,**kargs)
  File "D:\Phyton\bot\decorators.py", line 33, in wrap
    func(message)
  File "D:\Phyton\bot\bot.py", line 404, in choiceCard
    bot.register_next_step_handler(mess,nomCard)
  File "D:\Phyton\lib\site-packages\telebot\__init__.py", line 996, in register_next_step_handler
    chat_id = message.chat.id
AttributeError: 'NoneType' object has no attribute 'chat'
 

2017-11-08 15:14:44.418043~ Traceback (most recent call last):
  File "D:\Phyton\bot\decorators.py", line 10, in wrap
    func(*args,**kargs)
  File "D:\Phyton\bot\decorators.py", line 33, in wrap
    func(message)
  File "D:\Phyton\bot\bot.py", line 413, in choiceCard
    bot.register_next_step_handler(mess,nomCard)
  File "D:\Phyton\lib\site-packages\telebot\__init__.py", line 996, in register_next_step_handler
    chat_id = message.chat.id
AttributeError: 'NoneType' object has no attribute 'chat'
 

2017-11-08 15:15:36.659043~ Traceback (most recent call last):
  File "D:\Phyton\bot\decorators.py", line 10, in wrap
    func(*args,**kargs)
  File "D:\Phyton\bot\decorators.py", line 33, in wrap
    func(message)
  File "D:\Phyton\bot\bot.py", line 414, in choiceCard
    bot.register_next_step_handler(mess,nomCard)
  File "D:\Phyton\lib\site-packages\telebot\__init__.py", line 996, in register_next_step_handler
    chat_id = message.chat.id
AttributeError: 'NoneType' object has no attribute 'chat'
 

2017-11-08 15:15:52.178043~ Traceback (most recent call last):
  File "D:\Phyton\bot\decorators.py", line 10, in wrap
    func(*args,**kargs)
  File "D:\Phyton\bot\decorators.py", line 33, in wrap
    func(message)
  File "D:\Phyton\bot\bot.py", line 414, in choiceCard
    bot.register_next_step_handler(mess,nomCard)
  File "D:\Phyton\lib\site-packages\telebot\__init__.py", line 996, in register_next_step_handler
    chat_id = message.chat.id
AttributeError: 'NoneType' object has no attribute 'chat'
 

2017-11-08 15:19:53.337748~ Traceback (most recent call last):
  File "D:\Phyton\bot\decorators.py", line 10, in wrap
    func(*args,**kargs)
  File "D:\Phyton\bot\decorators.py", line 33, in wrap
    func(message)
  File "D:\Phyton\bot\bot.py", line 397, in choiceCard
    a=login.req(card1,card2,language[str(message.from_user.id)])
NameError: name 'card1' is not defined
 

2017-11-08 15:37:33.518433~ Traceback (most recent call last):
  File "D:\Phyton\bot\decorators.py", line 10, in wrap
    func(*args,**kargs)
  File "D:\Phyton\bot\bot.py", line 307, in balance
    bot.register_next_step_handler(mess,nomCard)
UnboundLocalError: local variable 'mess' referenced before assignment
 

2017-11-08 15:41:40.597433~ Traceback (most recent call last):
  File "D:\Phyton\bot\decorators.py", line 10, in wrap
    func(*args,**kargs)
  File "D:\Phyton\bot\decorators.py", line 33, in wrap
    func(message)
  File "D:\Phyton\bot\bot.py", line 411, in choiceCard
    bot.register_next_step_handler(mess,nomCard)
UnboundLocalError: local variable 'mess' referenced before assignment
 

2017-11-08 15:56:43.105717~ Traceback (most recent call last):
  File "D:\Phyton\bot\decorators.py", line 10, in wrap
    func(*args,**kargs)
TypeError: trans() missing 4 required positional arguments: 'log', 'pas', 'message', and 'keyboardG'
 

2017-11-08 15:56:43.185725~ Traceback (most recent call last):
  File "D:\Phyton\bot\decorators.py", line 10, in wrap
    func(*args,**kargs)
  File "D:\Phyton\bot\decorators.py", line 33, in wrap
    func(message)
  File "D:\Phyton\bot\bot.py", line 411, in choiceCard
    bot.register_next_step_handler(mess,nomCard)
UnboundLocalError: local variable 'mess' referenced before assignment
 

2017-11-08 15:58:21.086514~ Traceback (most recent call last):
  File "D:\Phyton\bot\decorators.py", line 10, in wrap
    func(*args,**kargs)
TypeError: trans() missing 4 required positional arguments: 'log', 'pas', 'message', and 'keyboardG'
 

2017-11-08 15:59:03.040709~ Traceback (most recent call last):
  File "D:\Phyton\bot\decorators.py", line 10, in wrap
    func(*args,**kargs)
  File "D:\Phyton\bot\bot.py", line 419, in trans
    trans2.comands=x
NameError: name 'trans2' is not defined
 

2017-11-08 15:59:38.431247~ Traceback (most recent call last):
  File "D:\Phyton\bot\decorators.py", line 10, in wrap
    func(*args,**kargs)
  File "D:\Phyton\bot\bot.py", line 420, in trans
    mess=bot.send_message(message.chat.id,config.text['textTransPeriod'][language[str(message.from_user.id)]],keyboard)
KeyError: 'textTransPeriod'

During handling of the above exception, another exception occurred:

Traceback (most recent call last):
  File "D:\Phyton\bot\decorators.py", line 10, in wrap
    func(*args,**kargs)
  File "D:\Phyton\bot\decorators.py", line 33, in wrap
    func(message)
  File "D:\Phyton\bot\bot.py", line 395, in choiceCard
    trans(card[0][1],card[0][2],message,keyboard)
  File "D:\Phyton\bot\decorators.py", line 12, in wrap
    langFunc(*args)
TypeError: selectLang() takes 1 positional argument but 4 were given
 

